<?xml version="1.0"?>
<robot xmlns:xacro="http://www.ros.org/wiki/xacro">

<xacro:include filename="inertial_macros.xacro"/>


  <xacro:property name="wheel_radius" value="0.05"/>
  <xacro:property name="wheel_width" value="0.03"/>
  <xacro:property name="wheel_x_offset" value="0.20"/>
  <xacro:property name="wheel_y_offset" value="0.15"/>

<!-- BASE_FOOTPRINT LINK -->

<joint name="base_footprint_joint" type="fixed">
	<parent link="base_link"/>
	<child link="base_footprint"/>
	<origin xyz="0 0 0" rpy="0 0 0"/>

</joint>

<link name="base_footprint">

</link>


  <link name="base_link">
    <inertial>
      <mass value="5.0"/>
      <origin xyz="0 0 0"/>
      <inertia ixx="0.1" ixy="0.0" ixz="0.0"
               iyy="0.1" iyz="0.0"
               izz="0.1"/>
    </inertial>

    <visual>
      <geometry>
        <box size="0.4 0.3 0.1"/>
      </geometry>
    </visual>
  </link>


  <xacro:macro name="wheel" params="name x y">
    <link name="${name}_link">
      <visual>
        <geometry>
          <cylinder radius="${wheel_radius}" length="${wheel_width}"/>
        </geometry>
      </visual>
      <inertial>
        <mass value="0.5"/>
        <origin xyz="0 0 0"/>
        <inertia ixx="0.001" ixy="0.0" ixz="0.0"
                 iyy="0.001" iyz="0.0"
                 izz="0.001"/>
      </inertial>
    </link>

    <joint name="${name}_joint" type="continuous">
      <parent link="base_link"/>
      <child link="${name}_link"/>
      <origin xyz="${x} ${y} 0" rpy="${pi/2} 0 0"/>
    
      <axis xyz="0 0 1"/>
    </joint>
  </xacro:macro>


  <xacro:wheel name="wheel_front_left"
               x="${wheel_x_offset}"
               y="${wheel_y_offset}"/>

  <xacro:wheel name="wheel_front_right"
               x="${wheel_x_offset}"
               y="-${wheel_y_offset}"/>

  <xacro:wheel name="wheel_rear_left"
               x="-${wheel_x_offset}"
               y="${wheel_y_offset}"/>

  <xacro:wheel name="wheel_rear_right"
               x="-${wheel_x_offset}"
               y="-${wheel_y_offset}"/>



</robot>
